![image-20200128220225591](C:\Users\Hery\Desktop\GitHub\java\image\image-20200128220225591.png)

**Error类**：不是错误，而是异常类。Error类型的异常表示程序运行环境出现了某种==致命==情况，

例如：==内存不够、堆栈溢出==等。一般不由应用程序处理，而是交给JVM处理。

**Exception类**：标识的异常通常是由应用程序本身所致。如程序出现这些异常，应用程序需要作出必要的反映。

#抛出-捕获try-catch

```java
public static void method() {
    try {
        int[] arr = {1, 2, 3};
        System.out.println(arr[3]);
        System.out.println("这里能够访问到吗");
    } catch (ArrayIndexOutOfBoundsException e) {
        System.out.println("你访问的数组索引不存在，请回去修改为正确的索引");
        e.printStackTrace();
    } finally {
        System.out.println("always print finally");
    }
}
```

- catch块的次序：**异常子类**的catch块放在**异常父类**的catch块前面。否则编译错误。
- 在catch块中，通常打印异常和与**异常相关的信息**：异常名称、产生异常的方法名等。
- 无论是否产生异常，都执行finally语句。finally语句不会捕获异常。
- 内层try捕获不到的异常由外层捕获和处理。


# throwable类

异常最高级父类

| 方法名                        | 说明                              |
| ----------------------------- | --------------------------------- |
| public String getMessage()    | 返回此 throwable 的详细消息字符串 |
| public String toString()      | 返回此可抛出的简短描述            |
| public void printStackTrace() | 把异常的错误信息输出在控制台      |

Index 3 out of bounds for length 3【e.getMessage】

-----------
java.lang.ArrayIndexOutOfBoundsException: Index 3 out of bounds for length 3【e】

-----------
java.lang.ArrayIndexOutOfBoundsException: Index 3 out of bounds for length 3 【e.printStackTrace()】
	at TryCatch.method(TryCatch.java:11)
	at TryCatch.main(TryCatch.java:4)

# 编译时异常&运行时异常

**==编译时异常==**

​	都是Exception类及其子类
​	必须显示处理，否则程序就会发生错误，无法通过编译

**try-catch或者throws，如果采用throws，谁调用谁处理**

**==运行时异常==**

- ClassCastException(类转换异常) 
- IndexOutOfBoundsException(数组越界) 
- NullPointerException(空指针) 
- ArrayStoreException(数据存储异常，操作数组时类型不一致) 
- IO操作的BufferOverflowException异常 

​	都是RuntimeException类及其子类
​	无需显式处理，也可以和编译时异常一样处理  

**可以不处理，直接回来改代码**

```java
public class ThrowsDemo {
    public static void main(String[] args) {
        System.out.println("begin");
        try {
            //method();可以回头修改
            method2();
        } catch (Exception e) {
            e.printStackTrace();
        }
        System.out.println("end");
    }
    //运行时异常
    public static void method() {
        int arr[] = {1, 2, 3};
        System.out.println(arr[3]);
    }
    //编译时异常
    public static void method2() throws ParseException {
        String s = "2018-08-08";
        SimpleDateFormat sdf = new SimpleDateFormat("yyyy-MM-dd");
        Date d = sdf.parse(s);
        System.out.println(d);
    }
}
```

# 自定义异常

![image-20200129213353568](C:\Users\Hery\Desktop\GitHub\java\image\image-20200129213353568.png)



自定义异常类继承于Exception类

```java
public class ScoreException extends Exception {
    public ScoreException() {
    }

    public ScoreException(String message) {
        super(message);
    }
}
```

方法声明时**throws**代表可能发生==异常类名==，不一定发生

具体代码块中需要**throw**==异常对象==，才能在被调用时==catch==

```java
public class Teacher {
    public void score(int s) throws ScoreException{
        if(s<=0||s>=100){
            throw new ScoreException("wrong score");
        }else{
            System.out.println("score="+s);
        }
    }
}
```

```java
public class Test {
    public static void main(String[] args) {
        Teacher t=new Teacher();
        try {
            t.score(-5);//可能抛出message=“wrong score”的ScoreException类异常
        } catch (ScoreException e) //形参接收{
            e.printStackTrace();
        }
    }
}
```


